Workbook

Sheet Dashboard
B1: U.S. Housing Market Dashboard
B2: Home prices: FHFA HPI (purchase-only, latest quarter 2026 Q2). Loans: CFPB HMDA originations (2018-2025). HPI is an index (1991 Q1 = 100), not a price.
B4: Select a state > | C4: Virginia | F4: Cards, charts, and the highlighted heat-map row update when you change the state. | N4: How to use
N5: 1. Pick a state in the yellow box. 2. The cards and the three charts show that state.
B6: Home price change, YoY (2026 Q2) | D6: Home price change since 2019 Q4 | G6: Loans originated (2025) | J6: Average loan size (2025) | N6: 3. The heat map shows all states. The selected state has a bold row. Latest HPI quarter: 2026 Q2.
B7: =INDEX(Calc!$D$2:$D$52,MATCH($C$4,Calc!$B$2:$B$52,0)) -> 0.030320098 | D7: =INDEX(Calc!$E$2:$E$52,MATCH($C$4,Calc!$B$2:$B$52,0)) -> 0.61808838 | G7: =SUMIFS(tblData[Total loans],tblData[State],$C$4,tblData[Year],2025) -> 164098 | J7: =SUMIFS(tblData[Total dollar volume],tblData[State],$C$4,tblData[Year],2025)/SUMIFS(tblData[Total loans],tblData[State],$C$4,tblData[Year],2025) -> 437686.75
B9: ="U.S.: "&TEXT(Calc!$I$2,"+0.0%;-0.0%;0.0%") -> U.S.: +2.1% | D9: ="U.S.: "&TEXT(Calc!$I$3,"+0.0%;-0.0%;0.0%") -> U.S.: +60.5% | G9: ="vs. 2024: "&TEXT(SUMIFS(tblData[Total loans],tblData[State],$C$4,tblData[Year],2025)/SUMIFS(tblData[Total loans],tblData[State],$C$4,tblData[Year],2024)-1,"+0.0%;-0.0%;0.0%") -> vs. 2024: +12.7% | J9: ="U.S.: "&TEXT(Calc!$I$4,"$#,##0") -> U.S.: $397,321
B11: Heat map: Q4 home price change, year over year (FHFA HPI, purchase-only, index_nsa)
B12: State | C12: 2018 | D12: 2019 | E12: 2020 | F12: 2021 | G12: 2022 | H12: 2023 | I12: 2024 | J12: 2025 | K12: Price trend | L12: Loans trend
B13: Alabama | C13: =SUMIFS(tblData[Q4 HPI YoY change],tblData[State],$B13,tblData[Year],C$12) -> 0.046723 | D13: =SUMIFS(tblData[Q4 HPI YoY change],tblData[State],$B13,tblData[Year],D$12) -> 0.065616 | E13: =SUMIFS(tblData[Q4 HPI YoY change],tblData[State],$B13,tblData[Year],E$12) -> 0.113352 | F13: =SUMIFS(tblData[Q4 HPI YoY change],tblData[State],$B13,tblData[Year],F$12) -> 0.170088 | G13: =SUMIFS(tblData[Q4 HPI YoY change],tblData[State],$B13,tblData[Year],G$12) -> 0.09743 | H13: =SUMIFS(tblData[Q4 HPI YoY change],tblData[State],$B13,tblData[Year],H$12) -> 0.041433 | I13: =SUMIFS(tblData[Q4 HPI YoY change],tblData[State],$B13,tblData[Year],I$12) -> 0.048609 | J13: =SUMIFS(tblData[Q4 HPI YoY change],tblData[State],$B13,tblData[Year],J$12) -> 0.024969
B14: Alaska | C14: =SUMIFS(tblData[Q4 HPI YoY change],tblData[State],$B14,tblData[Year],C$12) -> 0.013034 | D14: =SUMIFS(tblData[Q4 HPI YoY change],tblData[State],$B14,tblData[Year],D$12) -> 0.040887 | E14: =SUMIFS(tblData[Q4 HPI YoY change],tblData[State],$B14,tblData[Year],E$12) -> 0.085273 | F14: =SUMIFS(tblData[Q4 HPI YoY change],tblData[State],$B14,tblData[Year],F$12) -> 0.104741 | G14: =SUMIFS(tblData[Q4 HPI YoY change],tblData[State],$B14,tblData[Year],G$12) -> 0.055185 | H14: =SUMIFS(tblData[Q4 HPI YoY change],tblData[State],$B14,tblData[Year],H$12) -> 0.064347 | I14: =SUMIFS(tblData[Q4 HPI YoY change],tblData[State],$B14,tblData[Year],I$12) -> 0.038606 | J14: =SUMIFS(tblData[Q4 HPI YoY change],tblData[State],$B14,tblData[Year],J$12) -> 0.045982
B15: Arizona | C15: =SUMIFS(tblData[Q4 HPI YoY change],tblData[State],$B15,tblData[Year],C$12) -> 0.083673 | D15: =SUMIFS(tblData[Q4 HPI YoY change],tblData[State],$B15,tblData[Year],D$12) -> 0.079201 | E15: =SUMIFS(tblData[Q4 HPI YoY change],tblData[State],$B15,tblData[Year],E$12) -> 0.141687 | F15: =SUMIFS(tblData[Q4 HPI YoY change],tblData[State],$B15,tblData[Year],F$12) -> 0.272187 | G15: =SUMIFS(tblData[Q4 HPI YoY change],tblData[State],$B15,tblData[Year],G$12) -> 0.051615 | H15: =SUMIFS(tblData[Q4 HPI YoY change],tblData[State],$B15,tblData[Year],H$12) -> 0.057833 | I15: =SUMIFS(tblData[Q4 HPI YoY change],tblData[State],$B15,tblData[Year],I$12) -> 0.018212 | J15: =SUMIFS(tblData[Q4 HPI YoY change],tblData[State],$B15,tblData[Year],J$12) -> 0.00777
B16: Arkansas | C16: =SUMIFS(tblData[Q4 HPI YoY change],tblData[State],$B16,tblData[Year],C$12) -> 0.033379 | D16: =SUMIFS(tblData[Q4 HPI YoY change],tblData[State],$B16,tblData[Year],D$12) -> 0.039187 | E16: =SUMIFS(tblData[Q4 HPI YoY change],tblData[State],$B16,tblData[Year],E$12) -> 0.108858 | F16: =SUMIFS(tblData[Q4 HPI YoY change],tblData[State],$B16,tblData[Year],F$12) -> 0.185314 | G16: =SUMIFS(tblData[Q4 HPI YoY change],tblData[State],$B16,tblData[Year],G$12) -> 0.093785 | H16: =SUMIFS(tblData[Q4 HPI YoY change],tblData[State],$B16,tblData[Year],H$12) -> 0.056389 | I16: =SUMIFS(tblData[Q4 HPI YoY change],tblData[State],$B16,tblData[Year],I$12) -> 0.043951 | J16: =SUMIFS(tblData[Q4 HPI YoY change],tblData[State],$B16,tblData[Year],J$12) -> 0.040333
B17: California | C17: =SUMIFS(tblData[Q4 HPI YoY change],tblData[State],$B17,tblData[Year],C$12) -> 0.048003 | D17: =SUMIFS(tblData[Q4 HPI YoY change],tblData[State],$B17,tblData[Year],D$12) -> 0.044401 | E17: =SUMIFS(tblData[Q4 HPI YoY change],tblData[State],$B17,tblData[Year],E$12) -> 0.115793 | F17: =SUMIFS(tblData[Q4 HPI YoY change],tblData[State],$B17,tblData[Year],F$12) -> 0.191342 | G17: =SUMIFS(tblData[Q4 HPI YoY change],tblData[State],$B17,tblData[Year],G$12) -> 0.012414 | H17: =SUMIFS(tblData[Q4 HPI YoY change],tblData[State],$B17,tblData[Year],H$12) -> 0.048409 | I17: =SUMIFS(tblData[Q4 HPI YoY change],tblData[State],$B17,tblData[Year],I$12) -> 0.024759 | J17: =SUMIFS(tblData[Q4 HPI YoY change],tblData[State],$B17,tblData[Year],J$12) -> -0.00467
B18: Colorado | C18: =SUMIFS(tblData[Q4 HPI YoY change],tblData[State],$B18,tblData[Year],C$12) -> 0.068277 | D18: =SUMIFS(tblData[Q4 HPI YoY change],tblData[State],$B18,tblData[Year],D$12) -> 0.061513 | E18: =SUMIFS(tblData[Q4 HPI YoY change],tblData[State],$B18,tblData[Year],E$12) -> 0.108056 | F18: =SUMIFS(tblData[Q4 HPI YoY change],tblData[State],$B18,tblData[Year],F$12) -> 0.180695 | G18: =SUMIFS(tblData[Q4 HPI YoY change],tblData[State],$B18,tblData[Year],G$12) -> 0.047234 | H18: =SUMIFS(tblData[Q4 HPI YoY change],tblData[State],$B18,tblData[Year],H$12) -> 0.030588 | I18: =SUMIFS(tblData[Q4 HPI YoY change],tblData[State],$B18,tblData[Year],I$12) -> 0.022227 | J18: =SUMIFS(tblData[Q4 HPI YoY change],tblData[State],$B18,tblData[Year],J$12) -> -0.014876
B19: Connecticut | C19: =SUMIFS(tblData[Q4 HPI YoY change],tblData[State],$B19,tblData[Year],C$12) -> 0.023047 | D19: =SUMIFS(tblData[Q4 HPI YoY change],tblData[State],$B19,tblData[Year],D$12) -> 0.023353 | E19: =SUMIFS(tblData[Q4 HPI YoY change],tblData[State],$B19,tblData[Year],E$12) -> 0.135135 | F19: =SUMIFS(tblData[Q4 HPI YoY change],tblData[State],$B19,tblData[Year],F$12) -> 0.137121 | G19: =SUMIFS(tblData[Q4 HPI YoY change],tblData[State],$B19,tblData[Year],G$12) -> 0.088174 | H19: =SUMIFS(tblData[Q4 HPI YoY change],tblData[State],$B19,tblData[Year],H$12) -> 0.114507 | I19: =SUMIFS(tblData[Q4 HPI YoY change],tblData[State],$B19,tblData[Year],I$12) -> 0.089085 | J19: =SUMIFS(tblData[Q4 HPI YoY change],tblData[State],$B19,tblData[Year],J$12) -> 0.046341
B20: Delaware | C20: =SUMIFS(tblData[Q4 HPI YoY change],tblData[State],$B20,tblData[Year],C$12) -> 0.039282 | D20: =SUMIFS(tblData[Q4 HPI YoY change],tblData[State],$B20,tblData[Year],D$12) -> 0.070614 | E20: =SUMIFS(tblData[Q4 HPI YoY change],tblData[State],$B20,tblData[Year],E$12) -> 0.083585 | F20: =SUMIFS(tblData[Q4 HPI YoY change],tblData[State],$B20,tblData[Year],F$12) -> 0.153717 | G20: =SUMIFS(tblData[Q4 HPI YoY change],tblData[State],$B20,tblData[Year],G$12) -> 0.121628 | H20: =SUMIFS(tblData[Q4 HPI YoY change],tblData[State],$B20,tblData[Year],H$12) -> 0.045877 | I20: =SUMIFS(tblData[Q4 HPI YoY change],tblData[State],$B20,tblData[Year],I$12) -> 0.035142 | J20: =SUMIFS(tblData[Q4 HPI YoY change],tblData[State],$B20,tblData[Year],J$12) -> 0.069829
B21: District of Columbia | C21: =SUMIFS(tblData[Q4 HPI YoY change],tblData[State],$B21,tblData[Year],C$12) -> 0.058342 | D21: =SUMIFS(tblData[Q4 HPI YoY change],tblData[State],$B21,tblData[Year],D$12) -> 0.049369 | E21: =SUMIFS(tblData[Q4 HPI YoY change],tblData[State],$B21,tblData[Year],E$12) -> 0.034729 | F21: =SUMIFS(tblData[Q4 HPI YoY change],tblData[State],$B21,tblData[Year],F$12) -> 0.062777 | G21: =SUMIFS(tblData[Q4 HPI YoY change],tblData[State],$B21,tblData[Year],G$12) -> -0.041901 | H21: =SUMIFS(tblData[Q4 HPI YoY change],tblData[State],$B21,tblData[Year],H$12) -> 0.019263 | I21: =SUMIFS(tblData[Q4 HPI YoY change],tblData[State],$B21,tblData[Year],I$12) -> 0.02895 | J21: =SUMIFS(tblData[Q4 HPI YoY change],tblData[State],$B21,tblData[Year],J$12) -> -0.010255
B22: Florida | C22: =SUMIFS(tblData[Q4 HPI YoY change],tblData[State],$B22,tblData[Year],C$12) -> 0.069383 | D22: =SUMIFS(tblData[Q4 HPI YoY change],tblData[State],$B22,tblData[Year],D$12) -> 0.061315 | E22: =SUMIFS(tblData[Q4 HPI YoY change],tblData[State],$B22,tblData[Year],E$12) -> 0.118657 | F22: =SUMIFS(tblData[Q4 HPI YoY change],tblData[State],$B22,tblData[Year],F$12) -> 0.255416 | G22: =SUMIFS(tblData[Q4 HPI YoY change],tblData[State],$B22,tblData[Year],G$12) -> 0.130702 | H22: =SUMIFS(tblData[Q4 HPI YoY change],tblData[State],$B22,tblData[Year],H$12) -> 0.062616 | I22: =SUMIFS(tblData[Q4 HPI YoY change],tblData[State],$B22,tblData[Year],I$12) -> 0.020871 | J22: =SUMIFS(tblData[Q4 HPI YoY change],tblData[State],$B22,tblData[Year],J$12) -> -0.022847
B23: Georgia | C23: =SUMIFS(tblData[Q4 HPI YoY change],tblData[State],$B23,tblData[Year],C$12) -> 0.07463 | D23: =SUMIFS(tblData[Q4 HPI YoY change],tblData[State],$B23,tblData[Year],D$12) -> 0.066356 | E23: =SUMIFS(tblData[Q4 HPI YoY change],tblData[State],$B23,tblData[Year],E$12) -> 0.116115 | F23: =SUMIFS(tblData[Q4 HPI YoY change],tblData[State],$B23,tblData[Year],F$12) -> 0.205864 | G23: =SUMIFS(tblData[Q4 HPI YoY change],tblData[State],$B23,tblData[Year],G$12) -> 0.111059 | H23: =SUMIFS(tblData[Q4 HPI YoY change],tblData[State],$B23,tblData[Year],H$12) -> 0.064505 | I23: =SUMIFS(tblData[Q4 HPI YoY change],tblData[State],$B23,tblData[Year],I$12) -> 0.048148 | J23: =SUMIFS(tblData[Q4 HPI YoY change],tblData[State],$B23,tblData[Year],J$12) -> -0.000119
B24: Hawaii | C24: =SUMIFS(tblData[Q4 HPI YoY change],tblData[State],$B24,tblData[Year],C$12) -> 0.025632 | D24: =SUMIFS(tblData[Q4 HPI YoY change],tblData[State],$B24,tblData[Year],D$12) -> 0.037944 | E24: =SUMIFS(tblData[Q4 HPI YoY change],tblData[State],$B24,tblData[Year],E$12) -> 0.064385 | F24: =SUMIFS(tblData[Q4 HPI YoY change],tblData[State],$B24,tblData[Year],F$12) -> 0.206107 | G24: =SUMIFS(tblData[Q4 HPI YoY change],tblData[State],$B24,tblData[Year],G$12) -> 0.156991 | H24: =SUMIFS(tblData[Q4 HPI YoY change],tblData[State],$B24,tblData[Year],H$12) -> -0.035076 | I24: =SUMIFS(tblData[Q4 HPI YoY change],tblData[State],$B24,tblData[Year],I$12) -> 0.030448 | J24: =SUMIFS(tblData[Q4 HPI YoY change],tblData[State],$B24,tblData[Year],J$12) -> 0.004199
B25: Idaho | C25: =SUMIFS(tblData[Q4 HPI YoY change],tblData[State],$B25,tblData[Year],C$12) -> 0.123137 | D25: =SUMIFS(tblData[Q4 HPI YoY change],tblData[State],$B25,tblData[Year],D$12) -> 0.130599 | E25: =SUMIFS(tblData[Q4 HPI YoY change],tblData[State],$B25,tblData[Year],E$12) -> 0.202348 | F25: =SUMIFS(tblData[Q4 HPI YoY change],tblData[State],$B25,tblData[Year],F$12) -> 0.275594 | G25: =SUMIFS(tblData[Q4 HPI YoY change],tblData[State],$B25,tblData[Year],G$12) -> 0.02263 | H25: =SUMIFS(tblData[Q4 HPI YoY change],tblData[State],$B25,tblData[Year],H$12) -> 0.020462 | I25: =SUMIFS(tblData[Q4 HPI YoY change],tblData[State],$B25,tblData[Year],I$12) -> 0.055138 | J25: =SUMIFS(tblData[Q4 HPI YoY change],tblData[State],$B25,tblData[Year],J$12) -> -0.008246
B26: Illinois | C26: =SUMIFS(tblData[Q4 HPI YoY change],tblData[State],$B26,tblData[Year],C$12) -> 0.023629 | D26: =SUMIFS(tblData[Q4 HPI YoY change],tblData[State],$B26,tblData[Year],D$12) -> 0.030881 | E26: =SUMIFS(tblData[Q4 HPI YoY change],tblData[State],$B26,tblData[Year],E$12) -> 0.08171 | F26: =SUMIFS(tblData[Q4 HPI YoY change],tblData[State],$B26,tblData[Year],F$12) -> 0.119865 | G26: =SUMIFS(tblData[Q4 HPI YoY change],tblData[State],$B26,tblData[Year],G$12) -> 0.068677 | H26: =SUMIFS(tblData[Q4 HPI YoY change],tblData[State],$B26,tblData[Year],H$12) -> 0.084654 | I26: =SUMIFS(tblData[Q4 HPI YoY change],tblData[State],$B26,tblData[Year],I$12) -> 0.074245 | J26: =SUMIFS(tblData[Q4 HPI YoY change],tblData[State],$B26,tblData[Year],J$12) -> 0.063674 | N26: Source: CFPB HMDA, originated loans, 2018-2025 (latest HMDA year: 2025).
B27: Indiana | C27: =SUMIFS(tblData[Q4 HPI YoY change],tblData[State],$B27,tblData[Year],C$12) -> 0.063266 | D27: =SUMIFS(tblData[Q4 HPI YoY change],tblData[State],$B27,tblData[Year],D$12) -> 0.070688 | E27: =SUMIFS(tblData[Q4 HPI YoY change],tblData[State],$B27,tblData[Year],E$12) -> 0.122945 | F27: =SUMIFS(tblData[Q4 HPI YoY change],tblData[State],$B27,tblData[Year],F$12) -> 0.145498 | G27: =SUMIFS(tblData[Q4 HPI YoY change],tblData[State],$B27,tblData[Year],G$12) -> 0.088506 | H27: =SUMIFS(tblData[Q4 HPI YoY change],tblData[State],$B27,tblData[Year],H$12) -> 0.072336 | I27: =SUMIFS(tblData[Q4 HPI YoY change],tblData[State],$B27,tblData[Year],I$12) -> 0.065087 | J27: =SUMIFS(tblData[Q4 HPI YoY change],tblData[State],$B27,tblData[Year],J$12) -> 0.033455
B28: Iowa | C28: =SUMIFS(tblData[Q4 HPI YoY change],tblData[State],$B28,tblData[Year],C$12) -> 0.042857 | D28: =SUMIFS(tblData[Q4 HPI YoY change],tblData[State],$B28,tblData[Year],D$12) -> 0.030371 | E28: =SUMIFS(tblData[Q4 HPI YoY change],tblData[State],$B28,tblData[Year],E$12) -> 0.081794 | F28: =SUMIFS(tblData[Q4 HPI YoY change],tblData[State],$B28,tblData[Year],F$12) -> 0.110128 | G28: =SUMIFS(tblData[Q4 HPI YoY change],tblData[State],$B28,tblData[Year],G$12) -> 0.084251 | H28: =SUMIFS(tblData[Q4 HPI YoY change],tblData[State],$B28,tblData[Year],H$12) -> 0.058423 | I28: =SUMIFS(tblData[Q4 HPI YoY change],tblData[State],$B28,tblData[Year],I$12) -> 0.050961 | J28: =SUMIFS(tblData[Q4 HPI YoY change],tblData[State],$B28,tblData[Year],J$12) -> 0.037492
B29: Kansas | C29: =SUMIFS(tblData[Q4 HPI YoY change],tblData[State],$B29,tblData[Year],C$12) -> 0.054257 | D29: =SUMIFS(tblData[Q4 HPI YoY change],tblData[State],$B29,tblData[Year],D$12) -> 0.053045 | E29: =SUMIFS(tblData[Q4 HPI YoY change],tblData[State],$B29,tblData[Year],E$12) -> 0.109123 | F29: =SUMIFS(tblData[Q4 HPI YoY change],tblData[State],$B29,tblData[Year],F$12) -> 0.127275 | G29: =SUMIFS(tblData[Q4 HPI YoY change],tblData[State],$B29,tblData[Year],G$12) -> 0.081622 | H29: =SUMIFS(tblData[Q4 HPI YoY change],tblData[State],$B29,tblData[Year],H$12) -> 0.077653 | I29: =SUMIFS(tblData[Q4 HPI YoY change],tblData[State],$B29,tblData[Year],I$12) -> 0.055738 | J29: =SUMIFS(tblData[Q4 HPI YoY change],tblData[State],$B29,tblData[Year],J$12) -> 0.040752
B30: Kentucky | C30: =SUMIFS(tblData[Q4 HPI YoY change],tblData[State],$B30,tblData[Year],C$12) -> 0.049815 | D30: =SUMIFS(tblData[Q4 HPI YoY change],tblData[State],$B30,tblData[Year],D$12) -> 0.042367 | E30: =SUMIFS(tblData[Q4 HPI YoY change],tblData[State],$B30,tblData[Year],E$12) -> 0.111897 | F30: =SUMIFS(tblData[Q4 HPI YoY change],tblData[State],$B30,tblData[Year],F$12) -> 0.140152 | G30: =SUMIFS(tblData[Q4 HPI YoY change],tblData[State],$B30,tblData[Year],G$12) -> 0.093972 | H30: =SUMIFS(tblData[Q4 HPI YoY change],tblData[State],$B30,tblData[Year],H$12) -> 0.058498 | I30: =SUMIFS(tblData[Q4 HPI YoY change],tblData[State],$B30,tblData[Year],I$12) -> 0.065426 | J30: =SUMIFS(tblData[Q4 HPI YoY change],tblData[State],$B30,tblData[Year],J$12) -> 0.028846
B31: Louisiana | C31: =SUMIFS(tblData[Q4 HPI YoY change],tblData[State],$B31,tblData[Year],C$12) -> 0.020333 | D31: =SUMIFS(tblData[Q4 HPI YoY change],tblData[State],$B31,tblData[Year],D$12) -> 0.028804 | E31: =SUMIFS(tblData[Q4 HPI YoY change],tblData[State],$B31,tblData[Year],E$12) -> 0.062828 | F31: =SUMIFS(tblData[Q4 HPI YoY change],tblData[State],$B31,tblData[Year],F$12) -> 0.102555 | G31: =SUMIFS(tblData[Q4 HPI YoY change],tblData[State],$B31,tblData[Year],G$12) -> 0.047635 | H31: =SUMIFS(tblData[Q4 HPI YoY change],tblData[State],$B31,tblData[Year],H$12) -> 0.018015 | I31: =SUMIFS(tblData[Q4 HPI YoY change],tblData[State],$B31,tblData[Year],I$12) -> 0.006143 | J31: =SUMIFS(tblData[Q4 HPI YoY change],tblData[State],$B31,tblData[Year],J$12) -> 0.034617
B32: Maine | C32: =SUMIFS(tblData[Q4 HPI YoY change],tblData[State],$B32,tblData[Year],C$12) -> 0.069832 | D32: =SUMIFS(tblData[Q4 HPI YoY change],tblData[State],$B32,tblData[Year],D$12) -> 0.065837 | E32: =SUMIFS(tblData[Q4 HPI YoY change],tblData[State],$B32,tblData[Year],E$12) -> 0.140122 | F32: =SUMIFS(tblData[Q4 HPI YoY change],tblData[State],$B32,tblData[Year],F$12) -> 0.201607 | G32: =SUMIFS(tblData[Q4 HPI YoY change],tblData[State],$B32,tblData[Year],G$12) -> 0.125361 | H32: =SUMIFS(tblData[Q4 HPI YoY change],tblData[State],$B32,tblData[Year],H$12) -> 0.062433 | I32: =SUMIFS(tblData[Q4 HPI YoY change],tblData[State],$B32,tblData[Year],I$12) -> 0.074502 | J32: =SUMIFS(tblData[Q4 HPI YoY change],tblData[State],$B32,tblData[Year],J$12) -> 0.039422
B33: Maryland | C33: =SUMIFS(tblData[Q4 HPI YoY change],tblData[State],$B33,tblData[Year],C$12) -> 0.014273 | D33: =SUMIFS(tblData[Q4 HPI YoY change],tblData[State],$B33,tblData[Year],D$12) -> 0.032246 | E33: =SUMIFS(tblData[Q4 HPI YoY change],tblData[State],$B33,tblData[Year],E$12) -> 0.102182 | F33: =SUMIFS(tblData[Q4 HPI YoY change],tblData[State],$B33,tblData[Year],F$12) -> 0.107998 | G33: =SUMIFS(tblData[Q4 HPI YoY change],tblData[State],$B33,tblData[Year],G$12) -> 0.060533 | H33: =SUMIFS(tblData[Q4 HPI YoY change],tblData[State],$B33,tblData[Year],H$12) -> 0.053917 | I33: =SUMIFS(tblData[Q4 HPI YoY change],tblData[State],$B33,tblData[Year],I$12) -> 0.058991 | J33: =SUMIFS(tblData[Q4 HPI YoY change],tblData[State],$B33,tblData[Year],J$12) -> 0.012015
B34: Massachusetts | C34: =SUMIFS(tblData[Q4 HPI YoY change],tblData[State],$B34,tblData[Year],C$12) -> 0.051898 | D34: =SUMIFS(tblData[Q4 HPI YoY change],tblData[State],$B34,tblData[Year],D$12) -> 0.053945 | E34: =SUMIFS(tblData[Q4 HPI YoY change],tblData[State],$B34,tblData[Year],E$12) -> 0.111851 | F34: =SUMIFS(tblData[Q4 HPI YoY change],tblData[State],$B34,tblData[Year],F$12) -> 0.145 | G34: =SUMIFS(tblData[Q4 HPI YoY change],tblData[State],$B34,tblData[Year],G$12) -> 0.050164 | H34: =SUMIFS(tblData[Q4 HPI YoY change],tblData[State],$B34,tblData[Year],H$12) -> 0.087184 | I34: =SUMIFS(tblData[Q4 HPI YoY change],tblData[State],$B34,tblData[Year],I$12) -> 0.055343 | J34: =SUMIFS(tblData[Q4 HPI YoY change],tblData[State],$B34,tblData[Year],J$12) -> 0.02473
B35: Michigan | C35: =SUMIFS(tblData[Q4 HPI YoY change],tblData[State],$B35,tblData[Year],C$12) -> 0.068625 | D35: =SUMIFS(tblData[Q4 HPI YoY change],tblData[State],$B35,tblData[Year],D$12) -> 0.056864 | E35: =SUMIFS(tblData[Q4 HPI YoY change],tblData[State],$B35,tblData[Year],E$12) -> 0.111342 | F35: =SUMIFS(tblData[Q4 HPI YoY change],tblData[State],$B35,tblData[Year],F$12) -> 0.148944 | G35: =SUMIFS(tblData[Q4 HPI YoY change],tblData[State],$B35,tblData[Year],G$12) -> 0.062741 | H35: =SUMIFS(tblData[Q4 HPI YoY change],tblData[State],$B35,tblData[Year],H$12) -> 0.088399 | I35: =SUMIFS(tblData[Q4 HPI YoY change],tblData[State],$B35,tblData[Year],I$12) -> 0.050737 | J35: =SUMIFS(tblData[Q4 HPI YoY change],tblData[State],$B35,tblData[Year],J$12) -> 0.05854
B36: Minnesota | C36: =SUMIFS(tblData[Q4 HPI YoY change],tblData[State],$B36,tblData[Year],C$12) -> 0.054614 | D36: =SUMIFS(tblData[Q4 HPI YoY change],tblData[State],$B36,tblData[Year],D$12) -> 0.056821 | E36: =SUMIFS(tblData[Q4 HPI YoY change],tblData[State],$B36,tblData[Year],E$12) -> 0.09584 | F36: =SUMIFS(tblData[Q4 HPI YoY change],tblData[State],$B36,tblData[Year],F$12) -> 0.122799 | G36: =SUMIFS(tblData[Q4 HPI YoY change],tblData[State],$B36,tblData[Year],G$12) -> 0.044687 | H36: =SUMIFS(tblData[Q4 HPI YoY change],tblData[State],$B36,tblData[Year],H$12) -> 0.042144 | I36: =SUMIFS(tblData[Q4 HPI YoY change],tblData[State],$B36,tblData[Year],I$12) -> 0.04599 | J36: =SUMIFS(tblData[Q4 HPI YoY change],tblData[State],$B36,tblData[Year],J$12) -> 0.032849
B37: Mississippi | C37: =SUMIFS(tblData[Q4 HPI YoY change],tblData[State],$B37,tblData[Year],C$12) -> 0.05883 | D37: =SUMIFS(tblData[Q4 HPI YoY change],tblData[State],$B37,tblData[Year],D$12) -> 0.031616 | E37: =SUMIFS(tblData[Q4 HPI YoY change],tblData[State],$B37,tblData[Year],E$12) -> 0.07939 | F37: =SUMIFS(tblData[Q4 HPI YoY change],tblData[State],$B37,tblData[Year],F$12) -> 0.154781 | G37: =SUMIFS(tblData[Q4 HPI YoY change],tblData[State],$B37,tblData[Year],G$12) -> 0.074105 | H37: =SUMIFS(tblData[Q4 HPI YoY change],tblData[State],$B37,tblData[Year],H$12) -> 0.10409 | I37: =SUMIFS(tblData[Q4 HPI YoY change],tblData[State],$B37,tblData[Year],I$12) -> -0.006794 | J37: =SUMIFS(tblData[Q4 HPI YoY change],tblData[State],$B37,tblData[Year],J$12) -> 0.030845
B38: Missouri | C38: =SUMIFS(tblData[Q4 HPI YoY change],tblData[State],$B38,tblData[Year],C$12) -> 0.06051 | D38: =SUMIFS(tblData[Q4 HPI YoY change],tblData[State],$B38,tblData[Year],D$12) -> 0.060645 | E38: =SUMIFS(tblData[Q4 HPI YoY change],tblData[State],$B38,tblData[Year],E$12) -> 0.104047 | F38: =SUMIFS(tblData[Q4 HPI YoY change],tblData[State],$B38,tblData[Year],F$12) -> 0.151975 | G38: =SUMIFS(tblData[Q4 HPI YoY change],tblData[State],$B38,tblData[Year],G$12) -> 0.082252 | H38: =SUMIFS(tblData[Q4 HPI YoY change],tblData[State],$B38,tblData[Year],H$12) -> 0.070647 | I38: =SUMIFS(tblData[Q4 HPI YoY change],tblData[State],$B38,tblData[Year],I$12) -> 0.053062 | J38: =SUMIFS(tblData[Q4 HPI YoY change],tblData[State],$B38,tblData[Year],J$12) -> 0.046366
... B41: Nevada | C41: =SUMIFS(tblData[Q4 HPI YoY change],tblData[State],$B41,tblData[Year],C$12) -> 0.100194 | D41: =SUMIFS(tblData[Q4 HPI YoY change],tblData[State],$B41,tblData[Year],D$12) -> 0.044329 | E41: =SUMIFS(tblData[Q4 HPI YoY change],tblData[State],$B41,tblData[Year],E$12) -> 0.106814 | F41: =SUMIFS(tblData[Q4 HPI YoY change],tblData[State],$B41,tblData[Year],F$12) -> 0.231992 | G41: =SUMIFS(tblData[Q4 HPI YoY change],tblData[State],$B41,tblData[Year],G$12) -> 0.029086 | H41: =SUMIFS(tblData[Q4 HPI YoY change],tblData[State],$B41,tblData[Year],H$12) -> 0.035683 | I41: =SUMIFS(tblData[Q4 HPI YoY change],tblData[State],$B41,tblData[Year],I$12) -> 0.061365 | J41: =SUMIFS(tblData[Q4 HPI YoY change],tblData[State],$B41,tblData[Year],J$12) -> 0.007058
B42: New Hampshire | C42: =SUMIFS(tblData[Q4 HPI YoY change],tblData[State],$B42,tblData[Year],C$12) -> 0.056091 | D42: =SUMIFS(tblData[Q4 HPI YoY change],tblData[State],$B42,tblData[Year],D$12) -> 0.055404 | E42: =SUMIFS(tblData[Q4 HPI YoY change],tblData[State],$B42,tblData[Year],E$12) -> 0.143124 | F42: =SUMIFS(tblData[Q4 HPI YoY change],tblData[State],$B42,tblData[Year],F$12) -> 0.180258 | G42: =SUMIFS(tblData[Q4 HPI YoY change],tblData[State],$B42,tblData[Year],G$12) -> 0.09315 | H42: =SUMIFS(tblData[Q4 HPI YoY change],tblData[State],$B42,tblData[Year],H$12) -> 0.091799 | I42: =SUMIFS(tblData[Q4 HPI YoY change],tblData[State],$B42,tblData[Year],I$12) -> 0.075209 | J42: =SUMIFS(tblData[Q4 HPI YoY change],tblData[State],$B42,tblData[Year],J$12) -> 0.038506 | N42: Source: FHFA HPI, purchase-only, index_nsa (not seasonally adjusted). U.S. = FHFA quarterly U.S. index. Years 2018-2025.
B43: New Jersey | C43: =SUMIFS(tblData[Q4 HPI YoY change],tblData[State],$B43,tblData[Year],C$12) -> 0.035622 | D43: =SUMIFS(tblData[Q4 HPI YoY change],tblData[State],$B43,tblData[Year],D$12) -> 0.046998 | E43: =SUMIFS(tblData[Q4 HPI YoY change],tblData[State],$B43,tblData[Year],E$12) -> 0.120857 | F43: =SUMIFS(tblData[Q4 HPI YoY change],tblData[State],$B43,tblData[Year],F$12) -> 0.150044 | G43: =SUMIFS(tblData[Q4 HPI YoY change],tblData[State],$B43,tblData[Year],G$12) -> 0.080391 | H43: =SUMIFS(tblData[Q4 HPI YoY change],tblData[State],$B43,tblData[Year],H$12) -> 0.112325 | I43: =SUMIFS(tblData[Q4 HPI YoY change],tblData[State],$B43,tblData[Year],I$12) -> 0.087198 | J43: =SUMIFS(tblData[Q4 HPI YoY change],tblData[State],$B43,tblData[Year],J$12) -> 0.049905
B44: New Mexico | C44: =SUMIFS(tblData[Q4 HPI YoY change],tblData[State],$B44,tblData[Year],C$12) -> 0.040888 | D44: =SUMIFS(tblData[Q4 HPI YoY change],tblData[State],$B44,tblData[Year],D$12) -> 0.054617 | E44: =SUMIFS(tblData[Q4 HPI YoY change],tblData[State],$B44,tblData[Year],E$12) -> 0.115241 | F44: =SUMIFS(tblData[Q4 HPI YoY change],tblData[State],$B44,tblData[Year],F$12) -> 0.149212 | G44: =SUMIFS(tblData[Q4 HPI YoY change],tblData[State],$B44,tblData[Year],G$12) -> 0.096742 | H44: =SUMIFS(tblData[Q4 HPI YoY change],tblData[State],$B44,tblData[Year],H$12) -> 0.051891 | I44: =SUMIFS(tblData[Q4 HPI YoY change],tblData[State],$B44,tblData[Year],I$12) -> 0.059218 | J44: =SUMIFS(tblData[Q4 HPI YoY change],tblData[State],$B44,tblData[Year],J$12) -> 0.005933
B45: New York | C45: =SUMIFS(tblData[Q4 HPI YoY change],tblData[State],$B45,tblData[Year],C$12) -> 0.045687 | D45: =SUMIFS(tblData[Q4 HPI YoY change],tblData[State],$B45,tblData[Year],D$12) -> 0.048531 | E45: =SUMIFS(tblData[Q4 HPI YoY change],tblData[State],$B45,tblData[Year],E$12) -> 0.107852 | F45: =SUMIFS(tblData[Q4 HPI YoY change],tblData[State],$B45,tblData[Year],F$12) -> 0.133384 | G45: =SUMIFS(tblData[Q4 HPI YoY change],tblData[State],$B45,tblData[Year],G$12) -> 0.075436 | H45: =SUMIFS(tblData[Q4 HPI YoY change],tblData[State],$B45,tblData[Year],H$12) -> 0.092514 | I45: =SUMIFS(tblData[Q4 HPI YoY change],tblData[State],$B45,tblData[Year],I$12) -> 0.074105 | J45: =SUMIFS(tblData[Q4 HPI YoY change],tblData[State],$B45,tblData[Year],J$12) -> 0.055681
...

Sheet Data
A1: State code | B1: State | C1: Region | D1: Division | E1: Year | F1: Purchase loans | G1: Purchase volume | H1: Refinance loans | I1: Refinance volume | J1: Cash-out refi loans | K1: Cash-out refi volume | L1: Total loans | M1: Total dollar volume | N1: Avg loan size | O1: Q4 HPI YoY change
A2: AL | B2: Alabama | C2: South | D2: East South Central | E2: 2018 | F2: 64977 | G2: 12441015000 | H2: 15735 | I2: 2968945000 | J2: 12698 | K2: 2121790000 | L2: 93410 | M2: 17531750000 | N2: 187686.01 | O2: 0.046723
A3: AL | B3: Alabama | C3: South | D3: East South Central | E3: 2019 | F3: 69028 | G3: 14062010000 | H3: 25121 | I3: 5927115000 | J3: 15137 | K3: 2888135000 | L3: 109286 | M3: 22877260000 | N3: 209333.86 | O3: 0.065616
A4: AL | B4: Alabama | C4: South | D4: East South Central | E4: 2020 | F4: 80056 | G4: 17433210000 | H4: 72194 | I4: 16409490000 | J4: 21558 | K4: 4653220000 | L4: 173808 | M4: 38495920000 | N4: 221485.32 | O4: 0.113352
A5: AL | B5: Alabama | C5: South | D5: East South Central | E5: 2021 | F5: 88540 | G5: 21757490000 | H5: 64466 | I5: 14136150000 | J5: 31624 | K5: 6599270000 | L5: 184630 | M5: 42492910000 | N5: 230151.71 | O5: 0.170088
A6: AL | B6: Alabama | C6: South | D6: East South Central | E6: 2022 | F6: 73500 | G6: 20324570000 | H6: 16492 | I6: 4012090000 | J6: 21438 | K6: 4454040000 | L6: 111430 | M6: 28790700000 | N6: 258374.76 | O6: 0.09743
A7: AL | B7: Alabama | C7: South | D7: East South Central | E7: 2023 | F7: 59342 | G7: 15618320000 | H7: 8991 | I7: 2304845000 | J7: 10776 | K7: 2255870000 | L7: 79109 | M7: 20179035000 | N7: 255078.88 | O7: 0.041433
A8: AL | B8: Alabama | C8: South | D8: East South Central | E8: 2024 | F8: 61667 | G8: 16085195000 | H8: 13241 | I8: 3568665000 | J8: 12337 | K8: 2500695000 | L8: 87245 | M8: 22154555000 | N8: 253934.95 | O8: 0.048609
A9: AL | B9: Alabama | C9: South | D9: East South Central | E9: 2025 | F9: 63509 | G9: 17647305000 | H9: 17724 | I9: 5515480000 | J9: 15370 | K9: 3224830000 | L9: 96603 | M9: 26387615000 | N9: 273155.23 | O9: 0.024969
A10: AK | B10: Alaska | C10: West | D10: Pacific | E10: 2018 | F10: 8999 | G10: 2604125000 | H10: 1186 | I10: 287780000 | J10: 2122 | K10: 481150000 | L10: 12307 | M10: 3373055000 | N10: 274076.14 | O10: 0.013034
A11: AK | B11: Alaska | C11: West | D11: Pacific | E11: 2019 | F11: 9226 | G11: 2639130000 | H11: 3135 | I11: 929845000 | J11: 2086 | K11: 509440000 | L11: 14447 | M11: 4078415000 | N11: 282301.86 | O11: 0.040887
A12: AK | B12: Alaska | C12: West | D12: Pacific | E12: 2020 | F12: 10336 | G12: 3157330000 | H12: 11701 | I12: 3422115000 | J12: 3250 | K12: 844870000 | L12: 25287 | M12: 7424315000 | N12: 293602.05 | O12: 0.085273
A13: AK | B13: Alaska | C13: West | D13: Pacific | E13: 2021 | F13: 11892 | G13: 3938960000 | H13: 11157 | I13: 3116815000 | J13: 3983 | K13: 1056315000 | L13: 27032 | M13: 8112090000 | N13: 300092.11 | O13: 0.104741
... A409: WY | B409: Wyoming | C409: West | D409: Mountain | E409: 2025 | F409: 7320 | G409: 2578610000 | H409: 1900 | I409: 790450000 | J409: 2066 | K409: 502770000 | L409: 11286 | M409: 3871830000 | N409: 343064.86 | O409: 0.032775
A411: Sources: CFPB HMDA (originated loans, 2018-2025); FHFA HPI purchase-only, index_nsa (Q4 vs prior-year Q4).
A412: Built from public FHFA and CFPB data. Not an official Fannie Mae, FHFA, or CFPB product.

Sheet Pivot
A1: PivotTable: loans and average loan size by Census region and year
A2: Source: CFPB HMDA originated loans, 2018-2025. Average loan size = total dollar volume / total loans (calculated field). Right-click > Refresh after you edit the Data table.
B3: Year
B4: Loans (count) | J4: Average loan size | R4: Total Loans (count) | S4: Total Average loan size
A5: Region | B5: 2018 | C5: 2019 | D5: 2020 | E5: 2021 | F5: 2022 | G5: 2023 | H5: 2024 | I5: 2025 | J5: 2018 | K5: 2019 | L5: 2020 | M5: 2021 | N5: 2022 | O5: 2023 | P5: 2024 | Q5: 2025
A6: Midwest | B6: 1426742 | C6: 1730055 | D6: 2863346 | E6: 2825134 | F6: 1458566 | G6: 999757 | H6: 1106374 | I6: 1248891 | J6: 196729.92 | K6: 214206.35 | L6: 224584.95 | M6: 228750.68 | N6: 255069.75 | O6: 255086.94 | P6: 265744.41 | Q6: 291378.27 | R6: 13658865 | S6: 236151.45
A7: Northeast | B7: 933635 | C7: 1110121 | D7: 1766374 | E7: 1915895 | F7: 978278 | G7: 619449 | H7: 671115 | I7: 766890 | J7: 323474.64 | K7: 349444.99 | L7: 344370.46 | M7: 359118.27 | N7: 419369.28 | O7: 392737.8 | P7: 415569.51 | Q7: 451440.06 | R7: 8761757 | S7: 372630.05
A8: South | B8: 2505602 | C8: 3005961 | D8: 4860924 | E8: 5162525 | F8: 2887047 | G8: 1984330 | H8: 2140206 | I8: 2330693 | J8: 246357.16 | K8: 264180.5 | L8: 275635.56 | M8: 290291.71 | N8: 338104.23 | O8: 333859.85 | P8: 348042.31 | Q8: 359161.57 | R8: 24877288 | S8: 300292.36
A9: West | B9: 1766599 | C9: 2438576 | D9: 4278858 | E9: 4180730 | F9: 1670588 | G9: 916652 | H9: 1068010 | I9: 1222236 | J9: 374506.49 | K9: 401752.61 | L9: 388385.35 | M9: 426884.66 | N9: 509611.8 | O9: 499956.83 | P9: 523120.35 | Q9: 544384.03 | R9: 17542249 | S9: 434467.87
A10: Grand Total | B10: 6632578 | C10: 8284713 | D10: 13769502 | E10: 14084284 | F10: 6994479 | G10: 4520188 | H10: 4985705 | I10: 5568710 | J10: 280670.03 | K10: 305663.64 | L10: 308873.97 | M10: 327855.64 | N10: 373118.56 | O10: 358188.76 | P10: 376373.58 | Q10: 397321.05 | R10: 64840159 | S10: 332856.34
A37: Source: CFPB HMDA, originated loans 2018-2025 (latest HMDA year: 2025).
A38: Built from public FHFA and CFPB data. Not an official Fannie Mae, FHFA, or CFPB product.

Sheet Notes
A1: Notes and sources
A3: Source | B3: Link | C3: Used for
A4: FHFA House Price Index (HPI) master file | B4: https://www.fhfa.gov/hpi/download/monthly/hpi_master.csv | C4: Heat map, home price cards and charts (traditional, purchase-only; index_nsa for year over year, index_sa for levels and since 2019 Q4)
A5: CFPB HMDA Data Browser API | B5: https://ffiec.cfpb.gov/v2/data-browser-api/view/aggregations | C5: Loans and dollar volume by state, year, and loan purpose (originated loans only)
A6: U.S. Census Bureau regions and divisions | B6: https://www2.census.gov/geo/pdfs/maps-data/maps/reference/us_regdiv.pdf | C6: Region and division for each state
A9: Item | B9: Definition
A10: Latest period | B10: Latest complete HPI quarter: 2026 Q2. HMDA years: 2018-2025.
A11: HPI | B11: The HPI is an index, not a price. 1991 Q1 = 100 (January 1991 = 100 for monthly data).
A12: Q4 HPI YoY change | B12: State Q4 index_nsa divided by the same state's Q4 index_nsa one year earlier, minus 1.
A13: State YoY change (cards) | B13: State index_nsa for 2026 Q2 compared with the same quarter one year earlier.
A14: U.S. YoY change | B14: FHFA's quarterly U.S. index_nsa for 2026 Q2, compared with the same quarter one year earlier.
A15: Change since 2019 Q4 | B15: index_sa (seasonally adjusted) for 2026 Q2 compared with 2019 Q4, the last quarter before the pandemic. The two quarters are different seasons, so the seasonally adjusted index is used.
A16: HPI trend chart | B16: index_sa (seasonally adjusted), because the chart compares many different quarters.
A17: Loans | B17: HMDA originated loans (action taken = 1). Purposes: Home purchase (1), Refinance (31), Cash-out refinance (32).
A18: Avg loan size | B18: Total dollar volume / total loans for the three loan purposes. The PivotTable uses the calculated field 'Weighted loan size' (= sum of dollar volume / sum of loans).
A19: Sheets | B19: Dashboard (state drop-down, KPI cards, charts, heat map, sparklines); Data (tblData table); Pivot (PivotTable and PivotChart); Calc (formula helpers for the dashboard).
A20: Rebuild | B20: Run: .venv/bin/python analysis/build_workbook.py (reads data/ only).
A22: Facts from the data only. No forecasts and no investment advice.
A23: Built from public FHFA and CFPB data. Not an official Fannie Mae, FHFA, or CFPB product.

Sheet Calc
A1: State code | B1: State | C1: Region | D1: HPI YoY 2026 Q2 | E1: Change since 2019 Q4 | F1: HPI 2026 Q2 | H1: Metric | I1: Value | P1: Quarter | Q1: U.S. | R1: Selected state | S1: AL | T1: AK | U1: AZ | V1: AR | W1: CA | X1: CO | Y1: CT | Z1: DE | AA1: DC | AB1: FL | AC1: GA | AD1: HI | AE1: ID | AF1: IL | AG1: IN | AH1: IA | AI1: KS | AJ1: KY | AK1: LA | AL1: ME | AM1: MD | AN1: MA | AO1: MI | AP1: MN | AQ1: MS | AR1: MO | AS1: MT | AT1: NE | AU1: NV | AV1: NH | AW1: NJ | AX1: NM | AY1: NY | AZ1: NC | BA1: ND | BB1: OH | BC1: OK | BD1: OR | BE1: PA | BF1: RI | BG1: SC | BH1: SD | BI1: TN | BJ1: TX | BK1: UT | BL1: VT | BM1: VA | BN1: WA | BO1: WV | BP1: WI | BQ1: WY
A2: AL | B2: Alabama | C2: South | D2: 0.027938239 | E2: 0.62224237 | F2: 375.76 | H2: U.S. HPI YoY (2026 Q2) | I2: 0.020891943 | P2: 2015 Q1 | Q2: 209 | R2: =INDEX($S$2:$BQ$2,MATCH($I$7,$S$1:$BQ$1,0)) -> 219.68 | S2: 185.24 | T2: 241.18 | U2: 240.4 | V2: 187.74 | W2: 218.62 | X2: 327.52 | Y2: 160.47 | Z2: 181.86 | AA2: 418.02 | AB2: 225.16 | AC2: 185.52 | AD2: 213.16 | AE2: 229.53 | AF2: 176.55 | AG2: 169.97 | AH2: 210.62 | AI2: 203.57 | AJ2: 197.58 | AK2: 248.63 | AL2: 204.18 | AM2: 217.12 | AN2: 231.09 | AO2: 174.64 | AP2: 226.73 | AQ2: 184.32 | AR2: 191.59 | AS2: 327.79 | AT2: 215.83 | AU2: 180.32 | AV2: 206.95 | AW2: 210.3 | AX2: 210.62 | AY2: 203.58 | AZ2: 190.3 | BA2: 293.74 | BB2: 162.59 | BC2: 212.33 | BD2: 309.66 | BE2: 190 | BF2: 186.37 | BG2: 194.63 | BH2: 247.15 | BI2: 204.47 | BJ2: 226.71 | BK2: 300.13 | BL2: 203.95 | BM2: 219.68 | BN2: 252.04 | BO2: 195.42 | BP2: 211.44 | BQ2: 313.14
A3: AK | B3: Alaska | C3: West | D3: 0.082760069 | E3: 0.53656331 | F3: 407.85 | H3: U.S. change since 2019 Q4 | I3: 0.60492872 | P3: 2015 Q2 | Q3: 211.68 | R3: =INDEX($S$3:$BQ$3,MATCH($I$7,$S$1:$BQ$1,0)) -> 220.63 | S3: 188.57 | T3: 240.72 | U3: 243.62 | V3: 191.87 | W3: 221.64 | X3: 334.54 | Y3: 161.14 | Z3: 182.68 | AA3: 429.13 | AB3: 229.59 | AC3: 188.15 | AD3: 213.9 | AE3: 237.05 | AF3: 178.21 | AG3: 171.59 | AH3: 212.39 | AI3: 204.87 | AJ3: 199.01 | AK3: 250.55 | AL3: 211.03 | AM3: 219.28 | AN3: 234.51 | AO3: 178.55 | AP3: 232.49 | AQ3: 185.05 | AR3: 194.73 | AS3: 329.91 | AT3: 217.08 | AU3: 183.56 | AV3: 207.43 | AW3: 209.16 | AX3: 211.45 | AY3: 204.6 | AZ3: 192.43 | BA3: 293.13 | BB3: 164.39 | BC3: 211.56 | BD3: 319.13 | BE3: 192.19 | BF3: 187.28 | BG3: 196.65 | BH3: 249.1 | BI3: 205.71 | BJ3: 230.64 | BK3: 302.4 | BL3: 210.98 | BM3: 220.63 | BN3: 258.04 | BO3: 198.94 | BP3: 212.47 | BQ3: 312.27
A4: AZ | B4: Arizona | C4: West | D4: 0.0052214238 | E4: 0.64588071 | F4: 564.57 | H4: U.S. avg loan size (2025) | I4: =SUMIFS(tblData[Total dollar volume],tblData[Year],2025)/SUMIFS(tblData[Total loans],tblData[Year],2025) -> 397321.05 | P4: 2015 Q3 | Q4: 214.25 | R4: =INDEX($S$4:$BQ$4,MATCH($I$7,$S$1:$BQ$1,0)) -> 221.96 | S4: 188.85 | T4: 240.9 | U4: 249.41 | V4: 194.58 | W4: 225.38 | X4: 344.18 | Y4: 160.49 | Z4: 184.89 | AA4: 445.61 | AB4: 234.72 | AC4: 191.51 | AD4: 215.3 | AE4: 237.79 | AF4: 179.01 | AG4: 172.34 | AH4: 213.72 | AI4: 207.2 | AJ4: 200.64 | AK4: 252.93 | AL4: 208.75 | AM4: 220.01 | AN4: 236.41 | AO4: 179.26 | AP4: 234.2 | AQ4: 185.91 | AR4: 197.37 | AS4: 331.78 | AT4: 220.94 | AU4: 190.2 | AV4: 210.62 | AW4: 210.82 | AX4: 217.4 | AY4: 206.63 | AZ4: 195.82 | BA4: 295.05 | BB4: 165.63 | BC4: 214.36 | BD4: 327.59 | BE4: 194.08 | BF4: 189.21 | BG4: 196.15 | BH4: 251.11 | BI4: 209.2 | BJ4: 233.92 | BK4: 307.91 | BL4: 210.76 | BM4: 221.96 | BN4: 263.55 | BO4: 199 | BP4: 213.29 | BQ4: 316.71
A5: AR | B5: Arkansas | C5: South | D5: 0.010897698 | E5: 0.64149521 | F5: 370.19 | P5: 2015 Q4 | Q5: 217.28 | R5: =INDEX($S$5:$BQ$5,MATCH($I$7,$S$1:$BQ$1,0)) -> 224.43 | S5: 189.79 | T5: 244.77 | U5: 253.21 | V5: 195.28 | W5: 229.98 | X5: 349.66 | Y5: 161.03 | Z5: 187.86 | AA5: 437.46 | AB5: 240.32 | AC5: 193.63 | AD5: 220.73 | AE5: 247.79 | AF5: 179.8 | AG5: 174.31 | AH5: 217.74 | AI5: 207.94 | AJ5: 204.9 | AK5: 254.42 | AL5: 210.29 | AM5: 219.93 | AN5: 239 | AO5: 183.11 | AP5: 238.52 | AQ5: 189.63 | AR5: 199.95 | AS5: 335.36 | AT5: 222 | AU5: 193.54 | AV5: 212.11 | AW5: 211.45 | AX5: 214.38 | AY5: 207.16 | AZ5: 198.25 | BA5: 297.16 | BB5: 167.87 | BC5: 216.54 | BD5: 336.88 | BE5: 195.26 | BF5: 192.07 | BG5: 203.24 | BH5: 254.63 | BI5: 211.58 | BJ5: 237.36 | BK5: 315.75 | BL5: 207.88 | BM5: 224.43 | BN5: 272.17 | BO5: 203.77 | BP5: 216.53 | BQ5: 316.25
A6: CA | B6: California | C6: West | D6: -0.0028963666 | E6: 0.43404723 | F6: 417.15 | H6: Selected state | I6: =Dashboard!$C$4 -> Virginia | P6: 2016 Q1 | Q6: 219.95 | R6: =INDEX($S$6:$BQ$6,MATCH($I$7,$S$1:$BQ$1,0)) -> 226.61 | S6: 191.8 | T6: 245.15 | U6: 257.58 | V6: 195.83 | W6: 233.56 | X6: 359.11 | Y6: 160.71 | Z6: 187.9 | AA6: 434.79 | AB6: 245.38 | AC6: 195.89 | AD6: 220.77 | AE6: 250.11 | AF6: 180.66 | AG6: 175.65 | AH6: 218.45 | AI6: 212.67 | AJ6: 206.19 | AK6: 256.94 | AL6: 213.35 | AM6: 224.56 | AN6: 242.03 | AO6: 185.38 | AP6: 241.64 | AQ6: 189.36 | AR6: 204.4 | AS6: 339.44 | AT6: 221.82 | AU6: 198.83 | AV6: 212.64 | AW6: 211.98 | AX6: 214.5 | AY6: 208.52 | AZ6: 200.41 | BA6: 297.9 | BB6: 169.44 | BC6: 215.27 | BD6: 346.17 | BE6: 196.63 | BF6: 193.17 | BG6: 205.04 | BH6: 260.83 | BI6: 215.83 | BJ6: 241.5 | BK6: 321.94 | BL6: 206.88 | BM6: 226.61 | BN6: 277.79 | BO6: 200.17 | BP6: 219.5 | BQ6: 316.74
A7: CO | B7: Colorado | C7: West | D7: -0.0060726111 | E7: 0.41136459 | F7: 674.35 | H7: State code | I7: =INDEX($A$2:$A$52,MATCH($I$6,$B$2:$B$52,0)) -> VA | P7: 2016 Q2 | Q7: 223.11 | R7: =INDEX($S$7:$BQ$7,MATCH($I$7,$S$1:$BQ$1,0)) -> 228.25 | S7: 193.68 | T7: 247.5 | U7: 262.78 | V7: 197.56 | W7: 237.65 | X7: 367.69 | Y7: 161.23 | Z7: 189.32 | AA7: 459.37 | AB7: 251.1 | AC7: 200.28 | AD7: 217.47 | AE7: 253.23 | AF7: 182.65 | AG7: 179.12 | AH7: 220.73 | AI7: 215.07 | AJ7: 208.16 | AK7: 258.15 | AL7: 215.35 | AM7: 227.03 | AN7: 244.81 | AO7: 187.87 | AP7: 244.14 | AQ7: 190.07 | AR7: 203.62 | AS7: 341.92 | AT7: 226.83 | AU7: 202.56 | AV7: 217.45 | AW7: 214.91 | AX7: 219.88 | AY7: 212.1 | AZ7: 203.12 | BA7: 299.49 | BB7: 171.7 | BC7: 217.45 | BD7: 354.18 | BE7: 198.43 | BF7: 196.17 | BG7: 206.44 | BH7: 260.11 | BI7: 218.86 | BJ7: 245.53 | BK7: 327.59 | BL7: 209.6 | BM7: 228.25 | BN7: 284.25 | BO7: 203.54 | BP7: 222.37 | BQ7: 316.63
A8: CT | B8: Connecticut | C8: Northeast | D8: 0.045917875 | E8: 0.83055125 | F8: 319.12 | P8: 2016 Q3 | Q8: 226.44 | R8: =INDEX($S$8:$BQ$8,MATCH($I$7,$S$1:$BQ$1,0)) -> 230.76 | S8: 195.93 | T8: 247.06 | U8: 265.52 | V8: 199.08 | W8: 241.19 | X8: 377.69 | Y8: 161.33 | Z8: 190 | AA8: 453.3 | AB8: 257.98 | AC8: 203.67 | AD8: 219.68 | AE8: 261.52 | AF8: 185.31 | AG8: 181.78 | AH8: 223.7 | AI8: 216.86 | AJ8: 211.66 | AK8: 259.06 | AL8: 218.14 | AM8: 226.64 | AN8: 249.04 | AO8: 191.55 | AP8: 248.7 | AQ8: 191.57 | AR8: 207.39 | AS8: 344.17 | AT8: 229.77 | AU8: 204.99 | AV8: 218.49 | AW8: 215.92 | AX8: 217.94 | AY8: 213.69 | AZ8: 206.81 | BA8: 299.84 | BB8: 174.19 | BC8: 218.29 | BD8: 361.97 | BE8: 200.98 | BF8: 199.77 | BG8: 209.38 | BH8: 265.91 | BI8: 223.03 | BJ8: 250.36 | BK8: 334.68 | BL8: 213.27 | BM8: 230.76 | BN8: 291.79 | BO8: 202.62 | BP8: 225.01 | BQ8: 317.32
A9: DE | B9: Delaware | C9: South | D9: 0.032301003 | E9: 0.60793746 | F9: 347.62 | H9: Year | I9: Home purchase | J9: Refinance | K9: Cash-out refinance | L9: Avg loan size | M9: State Q4 HPI YoY | N9: U.S. Q4 HPI YoY | P9: 2016 Q4 | Q9: 229.93 | R9: =INDEX($S$9:$BQ$9,MATCH($I$7,$S$1:$BQ$1,0)) -> 232.67 | S9: 197.92 | T9: 247.32 | U9: 271.62 | V9: 199.95 | W9: 245.74 | X9: 387.13 | Y9: 162.9 | Z9: 189.78 | AA9: 469.62 | AB9: 262.88 | AC9: 206.93 | AD9: 230.73 | AE9: 265.03 | AF9: 187.77 | AG9: 184.23 | AH9: 225.07 | AI9: 220.89 | AJ9: 212.71 | AK9: 264.71 | AL9: 225.53 | AM9: 231.16 | AN9: 252.89 | AO9: 194.75 | AP9: 252.02 | AQ9: 194.38 | AR9: 210.51 | AS9: 357.32 | AT9: 231.07 | AU9: 211.55 | AV9: 221.32 | AW9: 217.15 | AX9: 222.31 | AY9: 217.02 | AZ9: 210.22 | BA9: 301.88 | BB9: 176.5 | BC9: 220 | BD9: 371.82 | BE9: 202.92 | BF9: 203.09 | BG9: 213.43 | BH9: 267.01 | BI9: 226.96 | BJ9: 253.26 | BK9: 340.79 | BL9: 212.36 | BM9: 232.67 | BN9: 299.74 | BO9: 202.49 | BP9: 228.66 | BQ9: 318.02
A10: DC | B10: District of Columbia | C10: South | D10: 0.015349385 | E10: 0.08585904 | F10: 604.4 | H10: 2018 | I10: =SUMIFS(tblData[Purchase loans],tblData[State code],$I$7,tblData[Year],$H10) -> 126055 | J10: =SUMIFS(tblData[Refinance loans],tblData[State code],$I$7,tblData[Year],$H10) -> 28560 | K10: =SUMIFS(tblData[Cash-out refi loans],tblData[State code],$I$7,tblData[Year],$H10) -> 29044 | L10: =SUMIFS(tblData[Total dollar volume],tblData[State code],$I$7,tblData[Year],$H10)/SUMIFS(tblData[Total loans],tblData[State code],$I$7,tblData[Year],$H10) -> 305832.68 | M10: =SUMIFS(tblData[Q4 HPI YoY change],tblData[State code],$I$7,tblData[Year],$H10) -> 0.044427 | N10: 0.054392447 | P10: 2017 Q1 | Q10: 232.89 | R10: =INDEX($S$10:$BQ$10,MATCH($I$7,$S$1:$BQ$1,0)) -> 234.11 | S10: 199.53 | T10: 249.63 | U10: 276.96 | V10: 203.13 | W10: 250.35 | X10: 394.22 | Y10: 163.32 | Z10: 190.17 | AA10: 473.6 | AB10: 267.95 | AC10: 210.14 | AD10: 223.46 | AE10: 272.82 | AF10: 189.7 | AG10: 185.64 | AH10: 227.74 | AI10: 221.3 | AJ10: 216.71 | AK10: 263.99 | AL10: 224.33 | AM10: 232.11 | AN10: 255.63 | AO10: 198.77 | AP10: 256.57 | AQ10: 194.4 | AR10: 211.76 | AS10: 356.56 | AT10: 236.19 | AU10: 214.39 | AV10: 229.62 | AW10: 217.59 | AX10: 225.51 | AY10: 218.63 | AZ10: 211.26 | BA10: 299.3 | BB10: 178.99 | BC10: 223.13 | BD10: 374.99 | BE10: 204.61 | BF10: 206.64 | BG10: 215.3 | BH10: 269.71 | BI10: 230.42 | BJ10: 257.39 | BK10: 347.8 | BL10: 224.82 | BM10: 234.11 | BN10: 307.33 | BO10: 201.58 | BP10: 231.7 | BQ10: 318.99
A11: FL | B11: Florida | C11: South | D11: 0.0091404336 | E11: 0.69699318 | F11: 547.45 | H11: 2019 | I11: =SUMIFS(tblData[Purchase loans],tblData[State code],$I$7,tblData[Year],$H11) -> 134404 | J11: =SUMIFS(tblData[Refinance loans],tblData[State code],$I$7,tblData[Year],$H11) -> 68456 | K11: =SUMIFS(tblData[Cash-out refi loans],tblData[State code],$I$7,tblData[Year],$H11) -> 37247 | L11: =SUMIFS(tblData[Total dollar volume],tblData[State code],$I$7,tblData[Year],$H11)/SUMIFS(tblData[Total loans],tblData[State code],$I$7,tblData[Year],$H11) -> 333847.06 | M11: =SUMIFS(tblData[Q4 HPI YoY change],tblData[State code],$I$7,tblData[Year],$H11) -> 0.053181 | N11: 0.054389722 | P11: 2017 Q2 | Q11: 236.86 | R11: =INDEX($S$11:$BQ$11,MATCH($I$7,$S$1:$BQ$1,0)) -> 237.65 | S11: 201.77 | T11: 247.25 | U11: 282.99 | V11: 203.27 | W11: 255.41 | X11: 404.33 | Y11: 164.42 | Z11: 191.47 | AA11: 475 | AB11: 273.66 | AC11: 214.03 | AD11: 237.06 | AE11: 278.65 | AF11: 189.16 | AG11: 187.92 | AH11: 229.46 | AI11: 225.12 | AJ11: 220.76 | AK11: 266.72 | AL11: 227.89 | AM11: 234.56 | AN11: 261.63 | AO11: 202.45 | AP11: 260.36 | AQ11: 195.51 | AR11: 216.81 | AS11: 362.08 | AT11: 240.63 | AU11: 218.04 | AV11: 229.29 | AW11: 221.12 | AX11: 226.64 | AY11: 221.3 | AZ11: 217.4 | BA11: 303.29 | BB11: 181.57 | BC11: 225.14 | BD11: 384.17 | BE11: 207.14 | BF11: 211.1 | BG11: 218.06 | BH11: 275.81 | BI11: 235.43 | BJ11: 263.49 | BK11: 356.53 | BL11: 217.73 | BM11: 237.65 | BN11: 316.59 | BO11: 203.57 | BP11: 235.64 | BQ11: 321.79
A12: GA | B12: Georgia | C12: South | D12: 0.018330132 | E12: 0.68431466 | F12: 425.66 | H12: 2020 | I12: =SUMIFS(tblData[Purchase loans],tblData[State code],$I$7,tblData[Year],$H12) -> 148659 | J12: =SUMIFS(tblData[Refinance loans],tblData[State code],$I$7,tblData[Year],$H12) -> 244471 | K12: =SUMIFS(tblData[Cash-out refi loans],tblData[State code],$I$7,tblData[Year],$H12) -> 56034 | L12: =SUMIFS(tblData[Total dollar volume],tblData[State code],$I$7,tblData[Year],$H12)/SUMIFS(tblData[Total loans],tblData[State code],$I$7,tblData[Year],$H12) -> 341921.06 | M12: =SUMIFS(tblData[Q4 HPI YoY change],tblData[State code],$I$7,tblData[Year],$H12) -> 0.105291 | N12: 0.11033159 | P12: 2017 Q3 | Q12: 240.44 | R12: =INDEX($S$12:$BQ$12,MATCH($I$7,$S$1:$BQ$1,0)) -> 240.19 | S12: 204.15 | T12: 250.81 | U12: 288.75 | V12: 206.26 | W12: 260.77 | X12: 410.97 | Y12: 166.15 | Z12: 194.27 | AA12: 487.2 | AB12: 278.26 | AC12: 216.93 | AD12: 247.11 | AE12: 284.29 | AF12: 191.2 | AG12: 190.71 | AH12: 231.63 | AI12: 227.05 | AJ12: 223.76 | AK12: 268.42 | AL12: 232.62 | AM12: 237.66 | AN12: 265.42 | AO12: 205.92 | AP12: 263.63 | AQ12: 198.88 | AR12: 218.37 | AS12: 367.42 | AT12: 242.68 | AU12: 225.9 | AV12: 233.13 | AW12: 224.81 | AX12: 229.23 | AY12: 225.71 | AZ12: 219.79 | BA12: 304.79 | BB12: 184.26 | BC12: 227.73 | BD12: 390.38 | BE12: 209.64 | BF12: 211.84 | BG12: 222.95 | BH12: 277.65 | BI12: 239.28 | BJ12: 266.6 | BK12: 365.83 | BL12: 218.72 | BM12: 240.19 | BN12: 324.08 | BO12: 203.41 | BP12: 238.95 | BQ12: 323.65
A13: HI | B13: Hawaii | C13: West | D13: 0.059349553 | E13: 0.60347389 | F13: 420.96 | H13: 2021 | I13: =SUMIFS(tblData[Purchase loans],tblData[State code],$I$7,tblData[Year],$H13) -> 167028 | J13: =SUMIFS(tblData[Refinance loans],tblData[State code],$I$7,tblData[Year],$H13) -> 198915 | K13: =SUMIFS(tblData[Cash-out refi loans],tblData[State code],$I$7,tblData[Year],$H13) -> 81112 | L13: =SUMIFS(tblData[Total dollar volume],tblData[State code],$I$7,tblData[Year],$H13)/SUMIFS(tblData[Total loans],tblData[State code],$I$7,tblData[Year],$H13) -> 346832.28 | M13: =SUMIFS(tblData[Q4 HPI YoY change],tblData[State code],$I$7,tblData[Year],$H13) -> 0.13443 | N13: 0.17312936 | P13: 2017 Q4 | Q13: 244.09 | R13: =INDEX($S$13:$BQ$13,MATCH($I$7,$S$1:$BQ$1,0)) -> 242.07 | S13: 207.59 | T13: 251.15 | U13: 293.03 | V13: 210.24 | W13: 265.39 | X13: 421.59 | Y13: 166.34 | Z13: 194.48 | AA13: 499.69 | AB13: 283.85 | AC13: 220.71 | AD13: 246.64 | AE13: 295.92 | AF13: 192.92 | AG13: 195.31 | AH13: 234.32 | AI13: 229.43 | AJ13: 226.2 | AK13: 270.31 | AL13: 234.03 | AM13: 240.54 | AN13: 268.79 | AO13: 209.67 | AP13: 267.75 | AQ13: 194.08 | AR13: 221.14 | AS13: 372.44 | AT13: 249.18 | AU13: 236.98 | AV13: 237.69 | AW13: 225.07 | AX13: 233.34 | AY13: 228.11 | AZ13: 223.83 | BA13: 302.13 | BB13: 186.98 | BC13: 228.8 | BD13: 395.83 | BE13: 212.32 | BF13: 216.25 | BG13: 226.27 | BH13: 280.08 | BI13: 244.55 | BJ13: 271.17 | BK13: 374.21 | BL13: 228.2 | BM13: 242.07 | BN13: 333 | BO13: 204.91 | BP13: 240.91 | BQ13: 326
A14: ID | B14: Idaho | C14: West | D14: 0.034792438 | E14: 0.74221927 | F14: 655.51 | H14: 2022 | I14: =SUMIFS(tblData[Purchase loans],tblData[State code],$I$7,tblData[Year],$H14) -> 130317 | J14: =SUMIFS(tblData[Refinance loans],tblData[State code],$I$7,tblData[Year],$H14) -> 27413 | K14: =SUMIFS(tblData[Cash-out refi loans],tblData[State code],$I$7,tblData[Year],$H14) -> 41261 | L14: =SUMIFS(tblData[Total dollar volume],tblData[State code],$I$7,tblData[Year],$H14)/SUMIFS(tblData[Total loans],tblData[State code],$I$7,tblData[Year],$H14) -> 375552.39 | M14: =SUMIFS(tblData[Q4 HPI YoY change],tblData[State code],$I$7,tblData[Year],$H14) -> 0.082709 | N14: 0.076199116 | P14: 2018 Q1 | Q14: 248.57 | R14: =INDEX($S$14:$BQ$14,MATCH($I$7,$S$1:$BQ$1,0)) -> 247.09 | S14: 209.46 | T14: 254.86 | U14: 301.55 | V14: 211.34 | W14: 270.78 | X14: 434.58 | Y14: 167.4 | Z14: 203.7 | AA14: 510.69 | AB14: 289.55 | AC14: 226.19 | AD14: 241.5 | AE14: 303.2 | AF14: 194.88 | AG14: 199.1 | AH14: 236.78 | AI14: 234.12 | AJ14: 229.55 | AK14: 272.06 | AL14: 238.85 | AM14: 242.38 | AN14: 272.94 | AO14: 214.51 | AP14: 273.12 | AQ14: 200.5 | AR14: 226.14 | AS14: 378.98 | AT14: 253.7 | AU14: 242.67 | AV14: 240.1 | AW14: 229.68 | AX14: 233.76 | AY14: 232.56 | AZ14: 228.12 | BA14: 304.93 | BB14: 190.44 | BC14: 228.49 | BD14: 407.16 | BE14: 215.47 | BF14: 221.31 | BG14: 230.12 | BH14: 285.6 | BI14: 248.15 | BJ14: 275.5 | BK14: 384.56 | BL14: 224.29 | BM14: 247.09 | BN14: 343.1 | BO14: 206.65 | BP14: 246.98 | BQ14: 329.44
A15: IL | B15: Illinois | C15: Midwest | D15: 0.055424601 | E15: 0.64443789 | F15: 334.38 | H15: 2023 | I15: =SUMIFS(tblData[Purchase loans],tblData[State code],$I$7,tblData[Year],$H15) -> 97993 | J15: =SUMIFS(tblData[Refinance loans],tblData[State code],$I$7,tblData[Year],$H15) -> 10567 | K15: =SUMIFS(tblData[Cash-out refi loans],tblData[State code],$I$7,tblData[Year],$H15) -> 17941 | L15: =SUMIFS(tblData[Total dollar volume],tblData[State code],$I$7,tblData[Year],$H15)/SUMIFS(tblData[Total loans],tblData[State code],$I$7,tblData[Year],$H15) -> 380744.38 | M15: =SUMIFS(tblData[Q4 HPI YoY change],tblData[State code],$I$7,tblData[Year],$H15) -> 0.071558 | N15: 0.06126857 | P15: 2018 Q2 | Q15: 251.42 | R15: =INDEX($S$15:$BQ$15,MATCH($I$7,$S$1:$BQ$1,0)) -> 247.58 | S15: 212.97 | T15: 253.45 | U15: 305.56 | V15: 213.02 | W15: 272.88 | X15: 439.46 | Y15: 167.79 | Z15: 202.88 | AA15: 516.88 | AB15: 295.29 | AC15: 230.32 | AD15: 246.53 | AE15: 313.81 | AF15: 195.82 | AG15: 202.4 | AH15: 240.62 | AI15: 236.17 | AJ15: 230.64 | AK15: 271.96 | AL15: 243.09 | AM15: 242.68 | AN15: 277.02 | AO15: 217.52 | AP15: 276.41 | AQ15: 202.42 | AR15: 227.65 | AS15: 381.77 | AT15: 255.44 | AU15: 252.63 | AV15: 242.74 | AW15: 230.19 | AX15: 235.94 | AY15: 234.37 | AZ15: 231.52 | BA15: 306.44 | BB15: 192.36 | BC15: 231.66 | BD15: 410.79 | BE15: 217.32 | BF15: 225.68 | BG15: 234.27 | BH15: 288.47 | BI15: 251.52 | BJ15: 278.5 | BK15: 393.82 | BL15: 226.4 | BM15: 247.58 | BN15: 349.5 | BO15: 207.9 | BP15: 251.07 | BQ15: 332.11
A16: IN | B16: Indiana | C16: Midwest | D16: 0.0345242 | E16: 0.67895635 | F16: 373.87 | H16: 2024 | I16: =SUMIFS(tblData[Purchase loans],tblData[State code],$I$7,tblData[Year],$H16) -> 102212 | J16: =SUMIFS(tblData[Refinance loans],tblData[State code],$I$7,tblData[Year],$H16) -> 20878 | K16: =SUMIFS(tblData[Cash-out refi loans],tblData[State code],$I$7,tblData[Year],$H16) -> 22530 | L16: =SUMIFS(tblData[Total dollar volume],tblData[State code],$I$7,tblData[Year],$H16)/SUMIFS(tblData[Total loans],tblData[State code],$I$7,tblData[Year],$H16) -> 407876.8 | M16: =SUMIFS(tblData[Q4 HPI YoY change],tblData[State code],$I$7,tblData[Year],$H16) -> 0.058691 | N16: 0.046090841 | P16: 2018 Q3 | Q16: 254.62 | R16: =INDEX($S$16:$BQ$16,MATCH($I$7,$S$1:$BQ$1,0)) -> 250.35 | S16: 215.26 | T16: 253.54 | U16: 310.53 | V16: 214.49 | W16: 276.36 | X16: 445.57 | Y16: 169.15 | Z16: 202.25 | AA16: 499.42 | AB16: 299.94 | AC16: 234.96 | AD16: 249.17 | AE16: 324.74 | AF16: 196.85 | AG16: 205.02 | AH16: 242.23 | AI16: 237.21 | AJ16: 233.1 | AK16: 273.08 | AL16: 246.17 | AM16: 244.03 | AN16: 279.81 | AO16: 220.77 | AP16: 280.4 | AQ16: 202.36 | AR16: 231.64 | AS16: 389.44 | AT16: 259.14 | AU16: 257.41 | AV16: 246.49 | AW16: 231.55 | AX16: 239.59 | AY16: 237.52 | AZ16: 234.96 | BA16: 306.47 | BB16: 195.56 | BC16: 233.94 | BD16: 415.71 | BE16: 219.34 | BF16: 229.22 | BG16: 237.27 | BH16: 295.17 | BI16: 257.03 | BJ16: 281.67 | BK16: 400.62 | BL16: 229.26 | BM16: 250.35 | BN16: 355.49 | BO16: 209.37 | BP16: 254.64 | BQ16: 334.45
A17: IA | B17: Iowa | C17: Midwest | D17: 0.022526572 | E17: 0.51051671 | F17: 380.62 | H17: 2025 | I17: =SUMIFS(tblData[Purchase loans],tblData[State code],$I$7,tblData[Year],$H17) -> 103337 | J17: =SUMIFS(tblData[Refinance loans],tblData[State code],$I$7,tblData[Year],$H17) -> 31796 | K17: =SUMIFS(tblData[Cash-out refi loans],tblData[State code],$I$7,tblData[Year],$H17) -> 28965 | L17: =SUMIFS(tblData[Total dollar volume],tblData[State code],$I$7,tblData[Year],$H17)/SUMIFS(tblData[Total loans],tblData[State code],$I$7,tblData[Year],$H17) -> 437686.75 | M17: =SUMIFS(tblData[Q4 HPI YoY change],tblData[State code],$I$7,tblData[Year],$H17) -> 0.037856 | N17: 0.020926756 | P17: 2018 Q4 | Q17: 257.39 | R17: =INDEX($S$17:$BQ$17,MATCH($I$7,$S$1:$BQ$1,0)) -> 252.98 | S17: 217.31 | T17: 254.71 | U17: 317.63 | V17: 217.09 | W17: 278.31 | X17: 450.3 | Y17: 170.18 | Z17: 201.98 | AA17: 529.7 | AB17: 303.71 | AC17: 237.13 | AD17: 252.83 | AE17: 332.35 | AF17: 197.34 | AG17: 207.79 | AH17: 244.43 | AI17: 241.9 | AJ17: 237.47 | AK17: 275.6 | AL17: 250.39 | AM17: 244.22 | AN17: 282.49 | AO17: 223.98 | AP17: 282.55 | AQ17: 205.46 | AR17: 234.63 | AS17: 389.51 | AT17: 262.49 | AU17: 260.99 | AV17: 251.01 | AW17: 232.89 | AX17: 243.06 | AY17: 238.66 | AZ17: 237.98 | BA17: 309.43 | BB17: 197.96 | BC17: 237.24 | BD17: 419.78 | BE17: 222 | BF17: 228.77 | BG17: 240.89 | BH17: 298.24 | BI17: 261.3 | BJ17: 285.03 | BK17: 409.87 | BL17: 233.66 | BM17: 252.98 | BN17: 358.86 | BO17: 205.22 | BP17: 257.95 | BQ17: 337.66
A18: KS | B18: Kansas | C18: Midwest | D18: 0.032146365 | E18: 0.63075897 | F18: 415.55 | H18: Chart titles | P18: 2019 Q1 | Q18: 260.51 | R18: =INDEX($S$18:$BQ$18,MATCH($I$7,$S$1:$BQ$1,0)) -> 255.15 | S18: 221.82 | T18: 258.59 | U18: 320.13 | V18: 220.64 | W18: 279.6 | X18: 454.19 | Y18: 170.84 | Z18: 199.66 | AA18: 509.57 | AB18: 308.49 | AC18: 240.18 | AD18: 254.31 | AE18: 344.47 | AF18: 199.05 | AG18: 212.36 | AH18: 246.38 | AI18: 244.68 | AJ18: 238.69 | AK18: 277.37 | AL18: 255.04 | AM18: 244.93 | AN18: 286.58 | AO18: 226.98 | AP18: 288.74 | AQ18: 207.02 | AR18: 237.05 | AS18: 392.06 | AT18: 264.64 | AU18: 266.72 | AV18: 252.94 | AW18: 235.04 | AX18: 245.4 | AY18: 240.2 | AZ18: 241.69 | BA18: 315.85 | BB18: 200.97 | BC18: 240.89 | BD18: 423.57 | BE18: 225.94 | BF18: 232.01 | BG18: 244.65 | BH18: 299.28 | BI18: 265.36 | BJ18: 288.06 | BK18: 416.32 | BL18: 236.5 | BM18: 255.15 | BN18: 364.6 | BO18: 214.59 | BP18: 261.4 | BQ18: 340.29
A19: KY | B19: Kentucky | C19: South | D19: 0.042576254 | E19: 0.65526156 | F19: 409.76 | H19: ="Loans originated by purpose, 2018-2025: "&$I$6 -> Loans originated by purpose, 2018-2025: Virginia | P19: 2019 Q2 | Q19: 263.54 | R19: =INDEX($S$19:$BQ$19,MATCH($I$7,$S$1:$BQ$1,0)) -> 258.98 | S19: 223.98 | T19: 263.22 | U19: 326.6 | V19: 222.72 | W19: 283.37 | X19: 462.64 | Y19: 172.02 | Z19: 209.13 | AA19: 519.52 | AB19: 311.28 | AC19: 244.2 | AD19: 253.44 | AE19: 350.91 | AF19: 200.58 | AG19: 214.85 | AH19: 246.43 | AI19: 246.45 | AJ19: 243.59 | AK19: 278.98 | AL19: 257.51 | AM19: 247.68 | AN19: 287.72 | AO19: 230.03 | AP19: 289.78 | AQ19: 208.15 | AR19: 239.36 | AS19: 405.74 | AT19: 268.77 | AU19: 268.65 | AV19: 257.76 | AW19: 236.24 | AX19: 249.07 | AY19: 243.4 | AZ19: 245.57 | BA19: 318.52 | BB19: 203.9 | BC19: 240.29 | BD19: 427.64 | BE19: 227.5 | BF19: 235.5 | BG19: 248.33 | BH19: 305.38 | BI19: 269.9 | BJ19: 290.92 | BK19: 423.8 | BL19: 238.68 | BM19: 258.98 | BN19: 368.83 | BO19: 214.45 | BP19: 264.79 | BQ19: 350.83
A20: LA | B20: Louisiana | C20: South | D20: 0.015855256 | E20: 0.29628846 | F20: 367.42 | H20: ="Q4 home price change, year over year: "&$I$6&" vs. U.S." -> Q4 home price change, year over year: Virginia vs. U.S. | P20: 2019 Q3 | Q20: 267 | R20: =INDEX($S$20:$BQ$20,MATCH($I$7,$S$1:$BQ$1,0)) -> 262.66 | S20: 227.71 | T20: 263.77 | U20: 333.95 | V20: 224.26 | W20: 287.22 | X20: 469.81 | Y20: 173.22 | Z20: 212.5 | AA20: 527.79 | AB20: 315.67 | AC20: 247.34 | AD20: 255.34 | AE20: 361.01 | AF20: 201.15 | AG20: 219.6 | AH20: 250.18 | AI20: 250.92 | AJ20: 244.93 | AK20: 280.7 | AL20: 262.94 | AM20: 250.24 | AN20: 291.97 | AO20: 232.87 | AP20: 293.81 | AQ20: 210.57 | AR20: 242.69 | AS20: 407.8 | AT20: 273.09 | AU20: 270.07 | AV20: 261.49 | AW20: 239.45 | AX20: 253.76 | AY20: 245.85 | AZ20: 248.66 | BA20: 316.16 | BB20: 206.71 | BC20: 244.8 | BD20: 434.49 | BE20: 229.8 | BF20: 238.34 | BG20: 250.3 | BH20: 304.01 | BI20: 273.72 | BJ20: 294.08 | BK20: 433.5 | BL20: 241.56 | BM20: 262.66 | BN20: 377.22 | BO20: 215.83 | BP20: 270.32 | BQ20: 352.96
A21: ME | B21: Maine | C21: Northeast | D21: 0.0097531364 | E21: 0.85635587 | F21: 495.35 | H21: ="House price index (1991 Q1 = 100), 2015 Q1-2026 Q2: "&$I$6&" vs. U.S." -> House price index (1991 Q1 = 100), 2015 Q1-2026 Q2: Virginia vs. U.S. | P21: 2019 Q4 | Q21: 271.47 | R21: =INDEX($S$21:$BQ$21,MATCH($I$7,$S$1:$BQ$1,0)) -> 266.58 | S21: 231.63 | T21: 265.43 | U21: 343.02 | V21: 225.52 | W21: 290.89 | X21: 477.8 | Y21: 174.33 | Z21: 216.19 | AA21: 556.61 | AB21: 322.6 | AC21: 252.72 | AD21: 262.53 | AE21: 376.25 | AF21: 203.34 | AG21: 222.68 | AH21: 251.98 | AI21: 254.82 | AJ21: 247.55 | AK21: 283.44 | AL21: 266.84 | AM21: 252.33 | AN21: 297.64 | AO21: 236.74 | AP21: 298.69 | AQ21: 212.19 | AR21: 249.03 | AS21: 416.37 | AT21: 274.14 | AU21: 272.88 | AV21: 265.11 | AW21: 243.63 | AX21: 256.58 | AY21: 250.44 | AZ21: 253.93 | BA21: 315.66 | BB21: 210.76 | BC21: 247.21 | BD21: 443.72 | BE21: 233.16 | BF21: 243.7 | BG21: 254.73 | BH21: 309.89 | BI21: 279.06 | BJ21: 298.66 | BK21: 442.82 | BL21: 243.24 | BM21: 266.58 | BN21: 387.09 | BO21: 220.87 | BP21: 274.89 | BQ21: 358.25
A22: MD | B22: Maryland | C22: South | D22: 0.009498256 | E22: 0.46189514 | F22: 368.88 | P22: 2020 Q1 | Q22: 276.66 | R22: =INDEX($S$22:$BQ$22,MATCH($I$7,$S$1:$BQ$1,0)) -> 272.54 | S22: 237.47 | T22: 267.5 | U22: 351.09 | V22: 228.51 | W22: 296.16 | X22: 485.98 | Y22: 176.81 | Z22: 216.11 | AA22: 551.9 | AB22: 330.45 | AC22: 258.7 | AD22: 268.76 | AE22: 388.75 | AF22: 205.49 | AG22: 228.58 | AH22: 255.19 | AI22: 257.47 | AJ22: 253.12 | AK22: 286.01 | AL22: 273.76 | AM22: 254.43 | AN22: 302.91 | AO22: 241.43 | AP22: 302.9 | AQ22: 215.07 | AR22: 252.56 | AS22: 437.48 | AT22: 281.51 | AU22: 278.61 | AV22: 271.62 | AW22: 249.2 | AX22: 263.92 | AY22: 254.58 | AZ22: 259.61 | BA22: 319.91 | BB22: 214.74 | BC22: 252.77 | BD22: 451.61 | BE22: 237.88 | BF22: 248.61 | BG22: 259.93 | BH22: 313.15 | BI22: 285.96 | BJ22: 303.15 | BK22: 456.7 | BL22: 256.38 | BM22: 272.54 | BN22: 397.38 | BO22: 216.53 | BP22: 279.49 | BQ22: 368.78
A23: MA | B23: Massachusetts | C23: Northeast | D23: 0.036297526 | E23: 0.62132106 | F23: 482.57 | P23: 2020 Q2 | Q23: 278.3 | R23: =INDEX($S$23:$BQ$23,MATCH($I$7,$S$1:$BQ$1,0)) -> 270.65 | S23: 239.03 | T23: 272 | U23: 357.47 | V23: 233.66 | W23: 296.78 | X23: 486.21 | Y23: 178.13 | Z23: 218.91 | AA23: 540.21 | AB23: 333.85 | AC23: 260.82 | AD23: 271.15 | AE23: 389.74 | AF23: 205.48 | AG23: 231.26 | AH23: 257.46 | AI23: 260.69 | AJ23: 255.33 | AK23: 290.01 | AL23: 275.93 | AM23: 256.58 | AN23: 301.27 | AO23: 241.74 | AP23: 305.23 | AQ23: 219.36 | AR23: 254.78 | AS23: 426.69 | AT23: 283.69 | AU23: 280.57 | AV23: 272.22 | AW23: 247.5 | AX23: 267.3 | AY23: 255.77 | AZ23: 260.97 | BA23: 321.21 | BB23: 218.21 | BC23: 257.25 | BD23: 451.3 | BE23: 238.78 | BF23: 245.64 | BG23: 263.16 | BH23: 318.68 | BI23: 289.3 | BJ23: 304.27 | BK23: 459.05 | BL23: 244.76 | BM23: 270.65 | BN23: 399.97 | BO23: 217.58 | BP23: 280.04 | BQ23: 367.94
